(dp1
S'output'
p2
S'<type \'exceptions.RuntimeError\'> Failure to connect, tried 5 times:\nTraceback (most recent call last):\n  File "/var/www/web2py/gluon/packages/dal/pydal/base.py", line 446, in __init__\n    self._adapter = ADAPTERS[self._dbname](**kwargs)\n  File "/var/www/web2py/gluon/packages/dal/pydal/adapters/base.py", line 60, in __call__\n    obj = super(AdapterMeta, cls).__call__(*args, **kwargs)\n  File "/var/www/web2py/gluon/packages/dal/pydal/adapters/sqlite.py", line 79, in __init__\n    if do_connect: self.reconnect()\n  File "/var/www/web2py/gluon/packages/dal/pydal/connection.py", line 104, in reconnect\n    self.connection = f()\n  File "/var/www/web2py/gluon/packages/dal/pydal/adapters/sqlite.py", line 77, in connector\n    return self.driver.Connection(dbpath, **driver_args)\nOperationalError: unable to open database file\n'
p3
sS'layer'
p4
S'/var/www/web2py/applications/tcc/models/conf.py'
p5
sS'code'
p6
S'# -*- coding: utf-8 -*-\ndb = DAL("sqlite://Scans.db", folder="/opt/web2py/applications/tcc/models", auto_import=True)\n\nfrom gluon.tools import Auth\n\n#Configura\xc3\xa7\xc3\xa3o Auth\nauth = Auth(db, controller="control",function="login")\nauth.settings.formstyle = "divs"\nauth.settings.login_next = URL(a=\'tcc\', c=\'control\', f=\'dash\')\nauth.settings.remember_me_form = False\nauth.settings.registration_requires_verification = False\nauth.settings.registration_requires_approval = False\nauth.settings.actions_disabled = [\'register\']\nauth.settings.expiration = 3600  # seconds\n\n#Mensagens de Erro\nauth.messages.logged_in = \'Bem Vindo\'\nauth.messages.access_denied = \'Acesso negado! Contate o administrador\'\nauth.messages.invalid_username = \'Usuario Inv\xc3\xa1lido \'\nauth.messages.invalid_login = \'Usuario ou Senha Inv\xc3\xa1lidos\'\nauth.messages.invalid_password = \'Senha Inv\xc3\xa1lida\'\nauth.messages.login_button = "Entrar"\nauth.messages.label_email = \'E-mail\'\nauth.messages.label_password = \'Password\''
p7
sS'snapshot'
p8
(dp9
sS'traceback'
p10
S'Traceback (most recent call last):\n  File "/var/www/web2py/gluon/restricted.py", line 227, in restricted\n    exec ccode in environment\n  File "/var/www/web2py/applications/tcc/models/conf.py", line 2, in <module>\n    db = DAL("sqlite://Scans.db", folder="/opt/web2py/applications/tcc/models", auto_import=True)\n  File "/var/www/web2py/gluon/packages/dal/pydal/base.py", line 174, in __call__\n    obj = super(MetaDAL, cls).__call__(*args, **kwargs)\n  File "/var/www/web2py/gluon/packages/dal/pydal/base.py", line 473, in __init__\n    "Failure to connect, tried %d times:\\n%s" % (attempts, tb)\nRuntimeError: Failure to connect, tried 5 times:\nTraceback (most recent call last):\n  File "/var/www/web2py/gluon/packages/dal/pydal/base.py", line 446, in __init__\n    self._adapter = ADAPTERS[self._dbname](**kwargs)\n  File "/var/www/web2py/gluon/packages/dal/pydal/adapters/base.py", line 60, in __call__\n    obj = super(AdapterMeta, cls).__call__(*args, **kwargs)\n  File "/var/www/web2py/gluon/packages/dal/pydal/adapters/sqlite.py", line 79, in __init__\n    if do_connect: self.reconnect()\n  File "/var/www/web2py/gluon/packages/dal/pydal/connection.py", line 104, in reconnect\n    self.connection = f()\n  File "/var/www/web2py/gluon/packages/dal/pydal/adapters/sqlite.py", line 77, in connector\n    return self.driver.Connection(dbpath, **driver_args)\nOperationalError: unable to open database file\n\n'
p11
s.